<?xml version="1.0" encoding="utf-8"?>
<!-- This URDF was automatically created by SolidWorks to URDF Exporter! Originally created by Stephen Brawner (brawner@gmail.com) 
     Commit Version: 1.6.0-4-g7f85cfe  Build Version: 1.6.7995.38578
     For more information, please see http://wiki.ros.org/sw_urdf_exporter -->
<robot
  name="dfdv_robot">
  <link
    name="base_link">
    <inertial>
      <origin
        xyz="-0.0473739694704758 -1.04609804765262E-07 -1.74506948306084E-06"
        rpy="0 0 0" />
      <mass
        value="0.624706350643648" />
      <inertia
        ixx="0.00511447442892371"
        ixy="0.00040821037597946"
        ixz="-4.56703849568947E-07"
        iyy="0.00343367420031374"
        iyz="-4.21131238551985E-07"
        izz="0.00839627365509467" />
    </inertial>
    <visual>
      <origin
        xyz="0 0 0"
        rpy="0 0 0" />
      <geometry>
        <mesh
          filename="package://dfdv_robot/meshes/base_link.STL" />
      </geometry>
      <material
        name="">
        <color
          rgba="0.792156862745098 0.819607843137255 0.933333333333333 1" />
      </material>
    </visual>
    <collision>
      <origin
        xyz="0 0 0"
        rpy="0 0 0" />
      <geometry>
        <mesh
          filename="package://dfdv_robot/meshes/base_link.STL" />
      </geometry>
    </collision>
  </link>
  <link
    name="l_wheel">
    <inertial>
      <origin
        xyz="-7.1785E-08 -0.0001059 0.0021198"
        rpy="0 0 0" />
      <mass
        value="2.5" />
      <inertia
        ixx="0.0022694"
        ixy="1.0307E-09"
        ixz="2.3276E-09"
        iyy="0.0022695"
        iyz="-6.9288E-06"
        izz="0.0039163" />
    </inertial>
    <visual>
      <origin
        xyz="0 0 0"
        rpy="0 0 0" />
      <geometry>
        <mesh
          filename="package://dfdv_robot/meshes/l_wheel.STL" />
      </geometry>
      <material
        name="">
        <color
          rgba="0.79216 0.81961 0.93333 1" />
      </material>
    </visual>
    <collision>
      <origin
        xyz="0 0 0"
        rpy="0 0 0" />
      <geometry>
        <mesh
          filename="package://dfdv_robot/meshes/l_wheel.STL" />
      </geometry>
    </collision>
  </link>
  <joint
    name="lf_joint"
    type="continuous">
    <origin
      xyz="-0.18435 -0.29904 -9.1429E-05"
      rpy="-1.5748 -0.10479 3.1416" />
    <parent
      link="base_link" />
    <child
      link="l_wheel" />
    <axis
      xyz="0 0.0039637 -0.99999" />
  </joint>
  <link
    name="r_wheel">
    <inertial>
      <origin
        xyz="7.1807E-08 0.0001059 0.0021198"
        rpy="0 0 0" />
      <mass
        value="2.5" />
      <inertia
        ixx="0.0022694"
        ixy="8.7606E-10"
        ixz="-2.3205E-09"
        iyy="0.0022695"
        iyz="6.9289E-06"
        izz="0.0039163" />
    </inertial>
    <visual>
      <origin
        xyz="0 0 0"
        rpy="0 0 0" />
      <geometry>
        <mesh
          filename="package://dfdv_robot/meshes/r_wheel.STL" />
      </geometry>
      <material
        name="">
        <color
          rgba="0.79216 0.81961 0.93333 1" />
      </material>
    </visual>
    <collision>
      <origin
        xyz="0 0 0"
        rpy="0 0 0" />
      <geometry>
        <mesh
          filename="package://dfdv_robot/meshes/r_wheel.STL" />
      </geometry>
    </collision>
  </link>
  <joint
    name="r_joint"
    type="continuous">
    <origin
      xyz="-0.18436 0.29904 -8.9705E-05"
      rpy="1.5748 -0.22065 3.1416" />
    <parent
      link="base_link" />
    <child
      link="r_wheel" />
    <axis
      xyz="0 0.0039637 0.99999" />
  </joint>
  <link
    name="caster">
    <inertial>
      <origin
        xyz="0 0 0"
        rpy="0 0 0" />
      <mass
        value="0.2" />
      <inertia
        ixx="0"
        ixy="0"
        ixz="0"
        iyy="0"
        iyz="0"
        izz="0" />
    </inertial>
    <visual>
      <origin
        xyz="0 0 0"
        rpy="0 0 0" />
      <geometry>
        <mesh
          filename="package://dfdv_robot/meshes/caster.STL" />
      </geometry>
      <material
        name="">
        <color
          rgba="1 1 1 1" />
      </material>
    </visual>
    <collision>
      <origin
        xyz="0 0 0"
        rpy="0 0 0" />
      <geometry>
        <mesh
          filename="package://dfdv_robot/meshes/caster.STL" />
      </geometry>
    </collision>
  </link>
  <joint
    name="caster_joint"
    type="continuous">
    <origin
      xyz="0.23671 0 0"
      rpy="0 0 0" />
    <parent
      link="base_link" />
    <child
      link="caster" />
    <axis
      xyz="0 0 1" />
  </joint>
  <link
    name="wc">
    <inertial>
      <origin
        xyz="0 -6.9389E-18 0"
        rpy="0 0 0" />
      <mass
        value="0.2" />
      <inertia
        ixx="9.5074E-06"
        ixy="3.1926E-24"
        ixz="5.7175E-21"
        iyy="9.5074E-06"
        iyz="-5.5214E-23"
        izz="1.4188E-05" />
    </inertial>
    <visual>
      <origin
        xyz="0 0 0"
        rpy="0 0 0" />
      <geometry>
        <mesh
          filename="package://dfdv_robot/meshes/wc.STL" />
      </geometry>
      <material
        name="">
        <color
          rgba="0.29412 0.29412 0.29412 1" />
      </material>
    </visual>
    <collision>
      <origin
        xyz="0 0 0"
        rpy="0 0 0" />
      <geometry>
        <mesh
          filename="package://dfdv_robot/meshes/wc.STL" />
      </geometry>
    </collision>
  </link>
  <joint
    name="wc_joint"
    type="continuous">
    <origin
      xyz="-0.021933 -0.0069236 -0.056768"
      rpy="1.5708 0 -2.8358" />
    <parent
      link="caster" />
    <child
      link="wc" />
    <axis
      xyz="0 0 1" />
  </joint>
</robot>
