<?xml version="1.0" ?>
<!-- =================================================================================== -->
<!-- |    This document was autogenerated by xacro from /home/mmh/ros_ws/src/test_robot/urdf/robot_.xacro | -->
<!-- |    EDITING THIS FILE BY HAND IS NOT RECOMMENDED                                 | -->
<!-- =================================================================================== -->
<!-- This URDF was automatically created by SolidWorks to URDF Exporter! Originally created by Stephen Brawner (brawner@gmail.com) 
     Commit Version: 1.6.0-4-g7f85cfe  Build Version: 1.6.7995.38578
     For more information, please see http://wiki.ros.org/sw_urdf_exporter -->
<robot name="robot_">
  <!-- This file is not a robot in and of itself, it just contains some useful tags that could be included in any robot -->
  <!-- Specify some colours -->
  <material name="white">
    <color rgba="1 1 1 1"/>
  </material>
  <material name="orange">
    <color rgba="1 0.3 0.1 1"/>
  </material>
  <material name="blue">
    <color rgba="0.2 0.2 1 1"/>
  </material>
  <!-- Specify some standard inertial calculations https://en.wikipedia.org/wiki/List_of_moments_of_inertia -->
  <!-- These make use of xacro's mathematical functionality -->
  <link name="base_link">
    <inertial>
      <origin rpy="0 0 0" xyz="0 0 0"/>
      <mass value="10"/>
      <inertia ixx="0.23541666666666666" ixy="0.0" ixz="0.0" iyy="0.20141666666666663" iyz="0.0" izz="0.43416666666666665"/>
    </inertial>
    <visual>
      <origin rpy="0 0 0" xyz="0 0 0"/>
      <geometry>
        <mesh filename="file:///home/mmh/ros_ws/install/test_robot/share/test_robot/meshes/base_link.STL"/>
      </geometry>
      <material name="">
        <color rgba="0.792156862745098 0.819607843137255 0.933333333333333 1"/>
      </material>
    </visual>
    <collision>
      <origin rpy="0 0 0" xyz="0 0 0"/>
      <geometry>
        <!--
        <mesh
          filename="file://$(find test_robot)/meshes/base_link.STL" />
      -->
        <box size="0.49 0.53 0.04"/>
      </geometry>
    </collision>
  </link>
  <link name="l_wheel">
    <inertial>
      <origin rpy="0 0 0" xyz="0 0 0"/>
      <mass value="2.5"/>
      <inertia ixx="0.004431302083333332" ixy="0.0" ixz="0.0" iyy="0.004431302083333332" iyz="0.0" izz="0.008"/>
    </inertial>
    <visual>
      <origin rpy="0 0 0" xyz="0 0 0"/>
      <geometry>
        <mesh filename="file:///home/mmh/ros_ws/install/test_robot/share/test_robot/meshes/l_wheel.STL"/>
      </geometry>
      <material name="">
        <color rgba="0.79216 0.81961 0.93333 1"/>
      </material>
    </visual>
    <collision>
      <origin rpy="0 0 0" xyz="0 0 0"/>
      <geometry>
        <!--
        <mesh
          filename="file://$(find test_robot)/meshes/l_wheel.STL" />
      -->
        <cylinder length="0.0455" radius="0.08"/>
      </geometry>
    </collision>
  </link>
  <joint name="lf_joint" type="continuous">
    <origin rpy="-1.5748 -0.10479 3.1416" xyz="-0.18435 -0.29904 -9.1429E-05"/>
    <parent link="base_link"/>
    <child link="l_wheel"/>
    <axis xyz="0 0.0039637 -0.99999"/>
  </joint>
  <link name="r_wheel">
    <inertial>
      <origin rpy="0 0 0" xyz="0 0 0"/>
      <mass value="2.5"/>
      <inertia ixx="0.004431302083333332" ixy="0.0" ixz="0.0" iyy="0.004431302083333332" iyz="0.0" izz="0.008"/>
    </inertial>
    <visual>
      <origin rpy="0 0 0" xyz="0 0 0"/>
      <geometry>
        <mesh filename="file:///home/mmh/ros_ws/install/test_robot/share/test_robot/meshes/r_wheel.STL"/>
      </geometry>
      <material name="">
        <color rgba="0.79216 0.81961 0.93333 1"/>
      </material>
    </visual>
    <collision>
      <origin rpy="0 0 0" xyz="0 0 0"/>
      <geometry>
        <!--
        <mesh
          filename="file://$(find test_robot)/meshes/r_wheel.STL" />
        -->
        <cylinder length="0.0455" radius="0.08"/>
      </geometry>
    </collision>
  </link>
  <joint name="r_joint" type="continuous">
    <origin rpy="1.5748 -0.22065 3.1416" xyz="-0.18436 0.29904 -8.9705E-05"/>
    <parent link="base_link"/>
    <child link="r_wheel"/>
    <axis xyz="0 0.0039637 0.99999"/>
  </joint>
  <link name="caster">
    <inertial>
      <origin rpy="0 0 0" xyz="0 0 0"/>
      <mass value="0.1"/>
      <inertia ixx="8.833333333333333e-05" ixy="0.0" ixz="0.0" iyy="9.749999999999998e-05" iyz="0.0" izz="5.0833333333333333e-05"/>
    </inertial>
    <visual>
      <origin rpy="0 0 0" xyz="0 0 0"/>
      <geometry>
        <mesh filename="file:///home/mmh/ros_ws/install/test_robot/share/test_robot/meshes/caster.STL"/>
      </geometry>
      <material name="">
        <color rgba="1 1 1 1"/>
      </material>
    </visual>
    <collision>
      <origin rpy="0 0 0" xyz="0 0 0"/>
      <geometry>
        <!--
        <mesh
          filename="file://$(find test_robot)/meshes/caster.STL" />
        -->
        <cylinder length="0.02" radius="0.03"/>
      </geometry>
    </collision>
  </link>
  <joint name="caster_joint" type="continuous">
    <origin rpy="0 0 0" xyz="0.23671 0 0"/>
    <parent link="base_link"/>
    <child link="caster"/>
    <axis xyz="0 0 1"/>
  </joint>
  <link name="wc">
    <inertial>
      <origin rpy="0 0 0" xyz="0 0 0"/>
      <mass value="0.2"/>
      <inertia ixx="0.00013460000000000002" ixy="0.0" ixz="0.0" iyy="0.00013460000000000002" iyz="0.0" izz="0.00025000000000000006"/>
    </inertial>
    <visual>
      <origin rpy="0 0 0" xyz="0 0 0"/>
      <geometry>
        <mesh filename="file:///home/mmh/ros_ws/install/test_robot/share/test_robot/meshes/wc.STL"/>
      </geometry>
      <material name="">
        <color rgba="0.29412 0.29412 0.29412 1"/>
      </material>
    </visual>
    <collision>
      <origin rpy="0 0 0" xyz="0 0 0"/>
      <geometry>
        <!--
        <mesh
          filename="file://$(find test_robot)/meshes/wc.STL" />
        -->
        <cylinder length="0.024" radius="0.025"/>
      </geometry>
    </collision>
  </link>
  <joint name="wc_joint" type="continuous">
    <origin rpy="1.5708 0 -2.8358" xyz="-0.021933 -0.0069236 -0.056768"/>
    <parent link="caster"/>
    <child link="wc"/>
    <axis xyz="0 0 1"/>
  </joint>
  <gazebo>
    <plugin filename="libgazebo_ros_diff_drive.so" name="diff_drive">
      <left_joint>r_joint</left_joint>
      <right_joint>lf_joint</right_joint>
      <wheel_separation>0.59808</wheel_separation>
      <wheel_diameter>0.08</wheel_diameter>
      <max_wheel_torque>200</max_wheel_torque>
      <max_wheel_acceleration>10.0</max_wheel_acceleration>
      <odometry_frame>odom</odometry_frame>
      <robot_base_frame>base_link</robot_base_frame>
      <publish_odom>true</publish_odom>
      <publish_odom_tf>true</publish_odom_tf>
      <publish_wheel_tf>true</publish_wheel_tf>
    </plugin>
  </gazebo>
  <gazebo reference="base_link">
    <material>Gazebo/Black</material>
  </gazebo>
  <gazebo reference="caster">
    <material>Gazebo/Green</material>
  </gazebo>
  <gazebo reference="wc">
    <material>Gazebo/Orange</material>
    <mu1 value="0.001"/>
    <mu2 value="0.001"/>
  </gazebo>
  <gazebo reference="l_wheel">
    <material>Gazebo/Blue</material>
  </gazebo>
  <gazebo reference="r_wheel">
    <material>Gazebo/Blue</material>
  </gazebo>
  <gazebo>
    <plugin filename="libgazebo_ros_joint_state_publisher.so" name="gazebo_ros_joint_state_publisher">
      <update_rate>20</update_rate>
      <joint_name>lf_joint</joint_name>
      <joint_name>r_joint</joint_name>
      <joint_name>caster_joint</joint_name>
      <joint_name>wc_joint</joint_name>
      <joint_name>base_joint</joint_name>
    </plugin>
  </gazebo>
  <gazebo>
    <plugin filename="libgazebo_ros_joint_pose_trajectory.so" name="gazebo_ros_joint_pose_trajectory">
      <update_rate>20</update_rate>
    </plugin>
  </gazebo>
</robot>
